2024-10-25 12:15:23,282 - INFO - check_files: 73 - ----------------Запускаем Check_file----------------
2024-10-25 12:15:23,285 - INFO - check_files: 74 - Проверка данных
2024-10-25 12:15:23,285 - INFO - check_files: 86 - Запуск на выполнение
2024-10-25 12:15:23,290 - INFO - run: 36 - Начинаем проверку файлов
2024-10-25 12:16:23,842 - INFO - check_files: 73 - ----------------Запускаем Check_file----------------
2024-10-25 12:16:23,843 - INFO - check_files: 74 - Проверка данных
2024-10-25 12:16:23,843 - INFO - check_files: 86 - Запуск на выполнение
2024-10-25 12:16:23,845 - INFO - run: 36 - Начинаем проверку файлов
2024-10-25 12:50:21,119 - INFO - check_files: 73 - ----------------Запускаем Check_file----------------
2024-10-25 12:50:21,126 - INFO - check_files: 74 - Проверка данных
2024-10-25 12:50:21,126 - INFO - check_files: 86 - Запуск на выполнение
2024-10-25 12:50:21,129 - INFO - run: 36 - Начинаем проверку файлов
2024-10-25 12:53:01,030 - ERROR - run: 109 - expected string or bytes-like object, got 'WindowsPath'
2024-10-25 12:53:01,408 - ERROR - run: 110 - Traceback (most recent call last):
  File "D:\python\Project_Check_File\check_file.py", line 69, in run
    if re.findall(pattern, excel_file):
       ^^^^^^^^^^^^^^^^^^^^^^^^^^^^^^^
  File "c:\Python312\Lib\re\__init__.py", line 217, in findall
    return _compile(pattern, flags).findall(string)
           ^^^^^^^^^^^^^^^^^^^^^^^^^^^^^^^^^^^^^^^^
TypeError: expected string or bytes-like object, got 'WindowsPath'

2024-10-25 12:53:02,584 - ERROR - run: 115 - ----------------Ошибка Check_file----------------
2024-10-25 12:53:30,373 - INFO - check_files: 73 - ----------------Запускаем Check_file----------------
2024-10-25 12:53:30,374 - INFO - check_files: 74 - Проверка данных
2024-10-25 12:53:30,374 - INFO - check_files: 86 - Запуск на выполнение
2024-10-25 12:53:30,376 - INFO - run: 36 - Начинаем проверку файлов
2024-10-25 13:39:09,728 - INFO - check_files: 73 - ----------------Запускаем Check_file----------------
2024-10-25 13:39:09,729 - INFO - check_files: 74 - Проверка данных
2024-10-25 13:39:09,729 - INFO - check_files: 86 - Запуск на выполнение
2024-10-25 13:39:09,732 - INFO - run: 36 - Начинаем проверку файлов
2024-10-25 13:41:28,038 - INFO - check_files: 73 - ----------------Запускаем Check_file----------------
2024-10-25 13:41:28,039 - INFO - check_files: 74 - Проверка данных
2024-10-25 13:41:28,039 - INFO - check_files: 86 - Запуск на выполнение
2024-10-25 13:41:28,043 - INFO - run: 36 - Начинаем проверку файлов
2024-10-25 13:41:28,485 - ERROR - run: 128 - No axis named slice(30, 3347, None) for object type DataFrame
2024-10-25 13:41:28,499 - ERROR - run: 129 - Traceback (most recent call last):
  File "c:\Python312\Lib\site-packages\pandas\core\generic.py", line 576, in _get_axis_number
    return cls._AXIS_TO_AXIS_NUMBER[axis]
           ~~~~~~~~~~~~~~~~~~~~~~~~^^^^^^
KeyError: slice(30, 3347, None)

During handling of the above exception, another exception occurred:

Traceback (most recent call last):
  File "D:\python\Project_Check_File\check_file.py", line 85, in run
    if len(df.iloc(slice(30, df.shape[0]))) != all_val:
           ^^^^^^^^^^^^^^^^^^^^^^^^^^^^^^^
  File "c:\Python312\Lib\site-packages\pandas\core\indexing.py", line 738, in __call__
    axis_int_none = self.obj._get_axis_number(axis)
                    ^^^^^^^^^^^^^^^^^^^^^^^^^^^^^^^
  File "c:\Python312\Lib\site-packages\pandas\core\generic.py", line 578, in _get_axis_number
    raise ValueError(f"No axis named {axis} for object type {cls.__name__}")
ValueError: No axis named slice(30, 3347, None) for object type DataFrame

2024-10-25 13:41:28,499 - ERROR - run: 134 - ----------------Ошибка Check_file----------------
2024-10-25 13:45:14,286 - INFO - check_files: 73 - ----------------Запускаем Check_file----------------
2024-10-25 13:45:14,287 - INFO - check_files: 74 - Проверка данных
2024-10-25 13:45:14,289 - INFO - check_files: 86 - Запуск на выполнение
2024-10-25 13:45:14,290 - INFO - run: 36 - Начинаем проверку файлов
2024-10-25 13:45:14,722 - ERROR - run: 132 - No axis named slice(30, 3347, None) for object type DataFrame
2024-10-25 13:45:14,727 - ERROR - run: 133 - Traceback (most recent call last):
  File "c:\Python312\Lib\site-packages\pandas\core\generic.py", line 576, in _get_axis_number
    return cls._AXIS_TO_AXIS_NUMBER[axis]
           ~~~~~~~~~~~~~~~~~~~~~~~~^^^^^^
KeyError: slice(30, 3347, None)

During handling of the above exception, another exception occurred:

Traceback (most recent call last):
  File "D:\python\Project_Check_File\check_file.py", line 87, in run
    if len(df.iloc(slice(30, df.shape[0]))) != all_val:
           ^^^^^^^^^^^^^^^^^^^^^^^^^^^^^^^
  File "c:\Python312\Lib\site-packages\pandas\core\indexing.py", line 738, in __call__
    axis_int_none = self.obj._get_axis_number(axis)
                    ^^^^^^^^^^^^^^^^^^^^^^^^^^^^^^^
  File "c:\Python312\Lib\site-packages\pandas\core\generic.py", line 578, in _get_axis_number
    raise ValueError(f"No axis named {axis} for object type {cls.__name__}")
ValueError: No axis named slice(30, 3347, None) for object type DataFrame

2024-10-25 13:45:14,727 - ERROR - run: 138 - ----------------Ошибка Check_file----------------
2024-10-25 13:45:43,605 - INFO - check_files: 73 - ----------------Запускаем Check_file----------------
2024-10-25 13:45:43,606 - INFO - check_files: 74 - Проверка данных
2024-10-25 13:45:43,606 - INFO - check_files: 86 - Запуск на выполнение
2024-10-25 13:45:43,609 - INFO - run: 36 - Начинаем проверку файлов
2024-10-25 13:47:12,451 - INFO - check_files: 73 - ----------------Запускаем Check_file----------------
2024-10-25 13:47:12,452 - INFO - check_files: 74 - Проверка данных
2024-10-25 13:47:12,453 - INFO - check_files: 86 - Запуск на выполнение
2024-10-25 13:47:12,455 - INFO - run: 36 - Начинаем проверку файлов
2024-10-25 13:48:18,219 - INFO - check_files: 73 - ----------------Запускаем Check_file----------------
2024-10-25 13:48:18,220 - INFO - check_files: 74 - Проверка данных
2024-10-25 13:48:18,220 - INFO - check_files: 86 - Запуск на выполнение
2024-10-25 13:48:18,222 - INFO - run: 36 - Начинаем проверку файлов
2024-10-25 13:48:56,473 - INFO - check_files: 73 - ----------------Запускаем Check_file----------------
2024-10-25 13:48:56,474 - INFO - check_files: 74 - Проверка данных
2024-10-25 13:48:56,475 - INFO - check_files: 86 - Запуск на выполнение
2024-10-25 13:48:56,477 - INFO - run: 36 - Начинаем проверку файлов
2024-10-25 13:49:17,922 - INFO - check_files: 73 - ----------------Запускаем Check_file----------------
2024-10-25 13:49:17,923 - INFO - check_files: 74 - Проверка данных
2024-10-25 13:49:17,923 - INFO - check_files: 86 - Запуск на выполнение
2024-10-25 13:49:17,925 - INFO - run: 36 - Начинаем проверку файлов
2024-10-25 13:53:35,287 - INFO - check_files: 73 - ----------------Запускаем Check_file----------------
2024-10-25 13:53:35,288 - INFO - check_files: 74 - Проверка данных
2024-10-25 13:53:35,288 - INFO - check_files: 86 - Запуск на выполнение
2024-10-25 13:53:35,291 - INFO - run: 36 - Начинаем проверку файлов
2024-10-25 13:53:35,733 - ERROR - run: 132 - 'Series' object has no attribute 'select_dtypes'
2024-10-25 13:53:35,745 - ERROR - run: 133 - Traceback (most recent call last):
  File "D:\python\Project_Check_File\check_file.py", line 89, in run
    tmp_df = df.iloc[slice(30, df.shape[0]), 0].select_dtypes(include='int64')
             ^^^^^^^^^^^^^^^^^^^^^^^^^^^^^^^^^^^^^^^^^^^^^^^^
  File "c:\Python312\Lib\site-packages\pandas\core\generic.py", line 6299, in __getattr__
    return object.__getattribute__(self, name)
           ^^^^^^^^^^^^^^^^^^^^^^^^^^^^^^^^^^^
AttributeError: 'Series' object has no attribute 'select_dtypes'. Did you mean: 'convert_dtypes'?

2024-10-25 13:53:35,745 - ERROR - run: 138 - ----------------Ошибка Check_file----------------
2024-10-25 13:55:41,230 - INFO - check_files: 73 - ----------------Запускаем Check_file----------------
2024-10-25 13:55:41,231 - INFO - check_files: 74 - Проверка данных
2024-10-25 13:55:41,231 - INFO - check_files: 86 - Запуск на выполнение
2024-10-25 13:55:41,233 - INFO - run: 36 - Начинаем проверку файлов
2024-10-25 13:59:26,008 - INFO - check_files: 73 - ----------------Запускаем Check_file----------------
2024-10-25 13:59:26,009 - INFO - check_files: 74 - Проверка данных
2024-10-25 13:59:26,009 - INFO - check_files: 86 - Запуск на выполнение
2024-10-25 13:59:26,011 - INFO - run: 36 - Начинаем проверку файлов
2024-10-25 13:59:26,481 - ERROR - run: 133 - 'list' object has no attribute 'size'
2024-10-25 13:59:26,484 - ERROR - run: 134 - Traceback (most recent call last):
  File "D:\python\Project_Check_File\check_file.py", line 89, in run
    int_number = [df.iloc[slice(30, df.shape[0]), 0].map(lambda x: isinstance(x, int))].size
                 ^^^^^^^^^^^^^^^^^^^^^^^^^^^^^^^^^^^^^^^^^^^^^^^^^^^^^^^^^^^^^^^^^^^^^^^^^^^
AttributeError: 'list' object has no attribute 'size'

2024-10-25 13:59:26,484 - ERROR - run: 139 - ----------------Ошибка Check_file----------------
2024-10-25 13:59:58,101 - INFO - check_files: 73 - ----------------Запускаем Check_file----------------
2024-10-25 13:59:58,102 - INFO - check_files: 74 - Проверка данных
2024-10-25 13:59:58,102 - INFO - check_files: 86 - Запуск на выполнение
2024-10-25 13:59:58,104 - INFO - run: 36 - Начинаем проверку файлов
2024-10-25 14:09:28,658 - INFO - check_files: 73 - ----------------Запускаем Check_file----------------
2024-10-25 14:09:28,660 - INFO - check_files: 74 - Проверка данных
2024-10-25 14:09:28,660 - INFO - check_files: 86 - Запуск на выполнение
2024-10-25 14:09:28,662 - INFO - run: 36 - Начинаем проверку файлов
2024-10-25 14:09:59,793 - INFO - check_files: 73 - ----------------Запускаем Check_file----------------
2024-10-25 14:09:59,794 - INFO - check_files: 74 - Проверка данных
2024-10-25 14:09:59,794 - INFO - check_files: 86 - Запуск на выполнение
2024-10-25 14:09:59,797 - INFO - run: 36 - Начинаем проверку файлов
2024-10-25 14:11:15,191 - INFO - check_files: 73 - ----------------Запускаем Check_file----------------
2024-10-25 14:11:15,192 - INFO - check_files: 74 - Проверка данных
2024-10-25 14:11:15,192 - INFO - check_files: 86 - Запуск на выполнение
2024-10-25 14:11:15,194 - INFO - run: 36 - Начинаем проверку файлов
2024-10-25 14:12:11,254 - ERROR - run: 135 - sequence item 0: expected str instance, int found
2024-10-25 14:12:11,906 - ERROR - run: 136 - Traceback (most recent call last):
  File "D:\python\Project_Check_File\check_file.py", line 94, in run
    error.append(f'кол-во целых значений в столбце 1 не соответствует типовому значению. Строки с ошибками: {', '.join(result)}')
                                                                                                             ^^^^^^^^^^^^^^^^^
TypeError: sequence item 0: expected str instance, int found

2024-10-25 14:12:13,235 - ERROR - run: 141 - ----------------Ошибка Check_file----------------
2024-10-25 14:13:24,737 - INFO - check_files: 73 - ----------------Запускаем Check_file----------------
2024-10-25 14:13:24,738 - INFO - check_files: 74 - Проверка данных
2024-10-25 14:13:24,738 - INFO - check_files: 86 - Запуск на выполнение
2024-10-25 14:13:24,740 - INFO - run: 36 - Начинаем проверку файлов
2024-10-25 14:16:46,057 - INFO - check_files: 73 - ----------------Запускаем Check_file----------------
2024-10-25 14:16:46,058 - INFO - check_files: 74 - Проверка данных
2024-10-25 14:16:46,059 - INFO - check_files: 86 - Запуск на выполнение
2024-10-25 14:16:46,061 - INFO - run: 36 - Начинаем проверку файлов
2024-10-25 14:17:31,866 - ERROR - run: 136 - index 3347 is out of bounds for axis 0 with size 3347
2024-10-25 14:17:32,212 - ERROR - run: 137 - Traceback (most recent call last):
  File "D:\python\Project_Check_File\check_file.py", line 96, in run
    if str(df.iloc[df.shape[0], 0]) != stop_val:
           ~~~~~~~^^^^^^^^^^^^^^^^
  File "c:\Python312\Lib\site-packages\pandas\core\indexing.py", line 1183, in __getitem__
    return self.obj._get_value(*key, takeable=self._takeable)
           ^^^^^^^^^^^^^^^^^^^^^^^^^^^^^^^^^^^^^^^^^^^^^^^^^^
  File "c:\Python312\Lib\site-packages\pandas\core\frame.py", line 4212, in _get_value
    return series._values[index]
           ~~~~~~~~~~~~~~^^^^^^^
IndexError: index 3347 is out of bounds for axis 0 with size 3347

2024-10-25 14:17:33,358 - ERROR - run: 142 - ----------------Ошибка Check_file----------------
2024-10-25 14:18:59,090 - INFO - check_files: 73 - ----------------Запускаем Check_file----------------
2024-10-25 14:18:59,091 - INFO - check_files: 74 - Проверка данных
2024-10-25 14:18:59,091 - INFO - check_files: 86 - Запуск на выполнение
2024-10-25 14:18:59,094 - INFO - run: 36 - Начинаем проверку файлов
2024-10-25 14:26:27,990 - INFO - check_files: 73 - ----------------Запускаем Check_file----------------
2024-10-25 14:26:27,991 - INFO - check_files: 74 - Проверка данных
2024-10-25 14:26:27,992 - INFO - check_files: 86 - Запуск на выполнение
2024-10-25 14:26:27,994 - INFO - run: 36 - Начинаем проверку файлов
2024-10-25 14:26:33,412 - ERROR - run: 114 - 'builtin_function_or_method' object is not subscriptable
2024-10-25 14:26:33,603 - ERROR - run: 115 - Traceback (most recent call last):
  File "D:\python\Project_Check_File\check_file.py", line 100, in run
    self.error_text.append[f"Папка {direcotry}, файл {file}, ошибки:\n {'\n'.join(number_error)}"]
    ~~~~~~~~~~~~~~~~~~~~~~^^^^^^^^^^^^^^^^^^^^^^^^^^^^^^^^^^^^^^^^^^^^^^^^^^^^^^^^^^^^^^^^^^^^^^^^
TypeError: 'builtin_function_or_method' object is not subscriptable

2024-10-25 14:26:34,361 - ERROR - run: 120 - ----------------Ошибка Check_file----------------
2024-10-25 14:27:06,980 - INFO - check_files: 73 - ----------------Запускаем Check_file----------------
2024-10-25 14:27:06,980 - INFO - check_files: 74 - Проверка данных
2024-10-25 14:27:06,980 - INFO - check_files: 86 - Запуск на выполнение
2024-10-25 14:27:06,982 - INFO - run: 36 - Начинаем проверку файлов
2024-10-25 14:28:01,300 - INFO - check_files: 73 - ----------------Запускаем Check_file----------------
2024-10-25 14:28:01,301 - INFO - check_files: 74 - Проверка данных
2024-10-25 14:28:01,301 - INFO - check_files: 86 - Запуск на выполнение
2024-10-25 14:28:01,303 - INFO - run: 36 - Начинаем проверку файлов
2024-10-25 14:29:50,910 - INFO - check_files: 73 - ----------------Запускаем Check_file----------------
2024-10-25 14:29:50,911 - INFO - check_files: 74 - Проверка данных
2024-10-25 14:29:50,911 - INFO - check_files: 86 - Запуск на выполнение
2024-10-25 14:29:50,913 - INFO - run: 36 - Начинаем проверку файлов
2024-10-25 14:29:50,915 - ERROR - run: 114 - 'str' object is not callable
2024-10-25 14:29:50,918 - ERROR - run: 115 - Traceback (most recent call last):
  File "D:\python\Project_Check_File\check_file.py", line 50, in run
    direcotry = os.path.pardir(excel_file.parent)
                ^^^^^^^^^^^^^^^^^^^^^^^^^^^^^^^^^
TypeError: 'str' object is not callable

2024-10-25 14:29:50,918 - ERROR - run: 120 - ----------------Ошибка Check_file----------------
2024-10-25 14:31:19,593 - INFO - check_files: 73 - ----------------Запускаем Check_file----------------
2024-10-25 14:31:19,594 - INFO - check_files: 74 - Проверка данных
2024-10-25 14:31:19,594 - INFO - check_files: 86 - Запуск на выполнение
2024-10-25 14:31:19,596 - INFO - run: 36 - Начинаем проверку файлов
2024-10-25 14:32:25,139 - INFO - check_files: 73 - ----------------Запускаем Check_file----------------
2024-10-25 14:32:25,140 - INFO - check_files: 74 - Проверка данных
2024-10-25 14:32:25,140 - INFO - check_files: 86 - Запуск на выполнение
2024-10-25 14:32:25,141 - INFO - run: 36 - Начинаем проверку файлов
2024-10-25 14:32:25,677 - INFO - run: 102 - Выводим ошибки
2024-10-25 14:32:42,820 - INFO - check_files: 73 - ----------------Запускаем Check_file----------------
2024-10-25 14:32:42,820 - INFO - check_files: 74 - Проверка данных
2024-10-25 14:32:42,821 - INFO - check_files: 86 - Запуск на выполнение
2024-10-25 14:32:42,822 - INFO - run: 36 - Начинаем проверку файлов
2024-10-25 14:32:43,359 - INFO - run: 102 - Выводим ошибки
