2024-10-24 15:02:54,549 - INFO - check_files: 73 - ----------------Запускаем Check_file----------------
2024-10-24 15:02:54,556 - INFO - check_files: 74 - Проверка данных
2024-10-24 15:03:03,361 - INFO - check_files: 73 - ----------------Запускаем Check_file----------------
2024-10-24 15:03:03,361 - INFO - check_files: 74 - Проверка данных
2024-10-24 15:03:25,600 - INFO - check_files: 73 - ----------------Запускаем Check_file----------------
2024-10-24 15:03:25,600 - INFO - check_files: 74 - Проверка данных
2024-10-24 15:05:32,322 - INFO - check_files: 73 - ----------------Запускаем Check_file----------------
2024-10-24 15:05:32,322 - INFO - check_files: 74 - Проверка данных
2024-10-24 15:05:32,328 - INFO - check_files: 86 - Запуск на выполнение
2024-10-24 15:05:32,329 - INFO - run: 48 - Начинаем проверку файлов
2024-10-24 15:05:32,330 - ERROR - run: 87 - 'str' object has no attribute 'rglob'
2024-10-24 15:05:32,331 - ERROR - run: 88 - Traceback (most recent call last):
  File "d:\python\Project_Check_File\check_file.py", line 51, in run
    for obj in self.folder.rglob():
               ^^^^^^^^^^^^^^^^^
AttributeError: 'str' object has no attribute 'rglob'

2024-10-24 15:05:32,331 - ERROR - run: 93 - ----------------Ошибка Check_file----------------
2024-10-24 15:06:13,017 - INFO - check_files: 73 - ----------------Запускаем Check_file----------------
2024-10-24 15:06:13,018 - INFO - check_files: 74 - Проверка данных
2024-10-24 15:06:13,018 - INFO - check_files: 86 - Запуск на выполнение
2024-10-24 15:06:13,019 - INFO - run: 48 - Начинаем проверку файлов
2024-10-24 15:06:13,019 - ERROR - run: 87 - Path.rglob() missing 1 required positional argument: 'pattern'
2024-10-24 15:06:13,020 - ERROR - run: 88 - Traceback (most recent call last):
  File "d:\python\Project_Check_File\check_file.py", line 51, in run
    for obj in pathlib.Path(self.folder).rglob():
               ^^^^^^^^^^^^^^^^^^^^^^^^^^^^^^^^^
TypeError: Path.rglob() missing 1 required positional argument: 'pattern'

2024-10-24 15:06:13,020 - ERROR - run: 93 - ----------------Ошибка Check_file----------------
2024-10-24 15:07:35,301 - INFO - check_files: 73 - ----------------Запускаем Check_file----------------
2024-10-24 15:07:35,301 - INFO - check_files: 74 - Проверка данных
2024-10-24 15:07:35,302 - INFO - check_files: 86 - Запуск на выполнение
2024-10-24 15:07:35,303 - INFO - run: 48 - Начинаем проверку файлов
2024-10-24 15:07:35,306 - INFO - run: 80 - ----------------Конец работы программы Check_file----------------
2024-10-24 15:08:48,551 - INFO - check_files: 73 - ----------------Запускаем Check_file----------------
2024-10-24 15:08:48,551 - INFO - check_files: 74 - Проверка данных
2024-10-24 15:08:48,551 - INFO - check_files: 86 - Запуск на выполнение
2024-10-24 15:08:48,552 - INFO - run: 48 - Начинаем проверку файлов
2024-10-24 15:08:48,557 - INFO - run: 80 - ----------------Конец работы программы Check_file----------------
2024-10-24 15:15:30,285 - INFO - check_files: 73 - ----------------Запускаем Check_file----------------
2024-10-24 15:15:30,286 - INFO - check_files: 74 - Проверка данных
2024-10-24 15:15:30,286 - INFO - check_files: 86 - Запуск на выполнение
2024-10-24 15:15:30,287 - INFO - run: 48 - Начинаем проверку файлов
2024-10-24 15:15:30,291 - INFO - run: 80 - ----------------Конец работы программы Check_file----------------
2024-10-24 15:32:37,201 - INFO - check_files: 73 - ----------------Запускаем Check_file----------------
2024-10-24 15:32:37,202 - INFO - check_files: 74 - Проверка данных
2024-10-24 15:32:37,202 - INFO - check_files: 86 - Запуск на выполнение
2024-10-24 15:32:37,203 - INFO - run: 35 - Начинаем проверку файлов
2024-10-24 15:32:37,213 - ERROR - run: 84 - Missing optional dependency 'openpyxl'.  Use pip or conda to install openpyxl.
2024-10-24 15:32:37,227 - ERROR - run: 85 - Traceback (most recent call last):
  File "c:\Python312\Lib\site-packages\pandas\compat\_optional.py", line 135, in import_optional_dependency
    module = importlib.import_module(name)
             ^^^^^^^^^^^^^^^^^^^^^^^^^^^^^
  File "c:\Python312\Lib\importlib\__init__.py", line 90, in import_module
    return _bootstrap._gcd_import(name[level:], package, level)
           ^^^^^^^^^^^^^^^^^^^^^^^^^^^^^^^^^^^^^^^^^^^^^^^^^^^^
  File "<frozen importlib._bootstrap>", line 1387, in _gcd_import
  File "<frozen importlib._bootstrap>", line 1360, in _find_and_load
  File "<frozen importlib._bootstrap>", line 1324, in _find_and_load_unlocked
ModuleNotFoundError: No module named 'openpyxl'

During handling of the above exception, another exception occurred:

Traceback (most recent call last):
  File "d:\python\Project_Check_File\check_file.py", line 49, in run
    df = pd.read_excel(excel_file)
         ^^^^^^^^^^^^^^^^^^^^^^^^^
  File "c:\Python312\Lib\site-packages\pandas\io\excel\_base.py", line 495, in read_excel
    io = ExcelFile(
         ^^^^^^^^^^
  File "c:\Python312\Lib\site-packages\pandas\io\excel\_base.py", line 1567, in __init__
    self._reader = self._engines[engine](
                   ^^^^^^^^^^^^^^^^^^^^^^
  File "c:\Python312\Lib\site-packages\pandas\io\excel\_openpyxl.py", line 552, in __init__
    import_optional_dependency("openpyxl")
  File "c:\Python312\Lib\site-packages\pandas\compat\_optional.py", line 138, in import_optional_dependency
    raise ImportError(msg)
ImportError: Missing optional dependency 'openpyxl'.  Use pip or conda to install openpyxl.

2024-10-24 15:32:37,228 - ERROR - run: 90 - ----------------Ошибка Check_file----------------
2024-10-24 15:33:33,419 - INFO - check_files: 73 - ----------------Запускаем Check_file----------------
2024-10-24 15:33:33,419 - INFO - check_files: 74 - Проверка данных
2024-10-24 15:33:33,419 - INFO - check_files: 86 - Запуск на выполнение
2024-10-24 15:33:33,421 - INFO - run: 35 - Начинаем проверку файлов
2024-10-24 15:33:34,115 - INFO - run: 77 - ----------------Конец работы программы Check_file----------------
2024-10-24 15:34:45,820 - INFO - check_files: 73 - ----------------Запускаем Check_file----------------
2024-10-24 15:34:45,820 - INFO - check_files: 74 - Проверка данных
2024-10-24 15:34:45,820 - INFO - check_files: 86 - Запуск на выполнение
2024-10-24 15:34:45,821 - INFO - run: 35 - Начинаем проверку файлов
2024-10-24 15:34:46,325 - INFO - run: 77 - ----------------Конец работы программы Check_file----------------
2024-10-24 15:39:32,964 - INFO - check_files: 73 - ----------------Запускаем Check_file----------------
2024-10-24 15:39:32,965 - INFO - check_files: 74 - Проверка данных
2024-10-24 15:39:32,965 - INFO - check_files: 86 - Запуск на выполнение
2024-10-24 15:39:44,102 - INFO - run: 35 - Начинаем проверку файлов
2024-10-24 15:40:33,145 - INFO - check_files: 73 - ----------------Запускаем Check_file----------------
2024-10-24 15:40:33,147 - INFO - check_files: 74 - Проверка данных
2024-10-24 15:40:33,147 - INFO - check_files: 86 - Запуск на выполнение
2024-10-24 15:40:33,149 - INFO - run: 35 - Начинаем проверку файлов
2024-10-24 15:45:44,220 - INFO - check_files: 73 - ----------------Запускаем Check_file----------------
2024-10-24 15:45:44,221 - INFO - check_files: 74 - Проверка данных
2024-10-24 15:45:44,221 - INFO - check_files: 86 - Запуск на выполнение
2024-10-24 15:45:44,224 - INFO - run: 35 - Начинаем проверку файлов
2024-10-24 16:32:56,635 - INFO - check_files: 73 - ----------------Запускаем Check_file----------------
2024-10-24 16:32:56,638 - INFO - check_files: 74 - Проверка данных
2024-10-24 16:32:56,638 - INFO - check_files: 86 - Запуск на выполнение
2024-10-24 16:32:56,642 - INFO - run: 35 - Начинаем проверку файлов
2024-10-24 16:33:05,742 - ERROR - run: 85 - 'str' object has no attribute 'value'
2024-10-24 16:33:05,742 - ERROR - run: 86 - Traceback (most recent call last):
  File "D:\python\Project_Check_File\check_file.py", line 50, in run
    print(datetime.datetime.strftime(df.iloc[3, 1].value), '%d.%B %Y')
                                     ^^^^^^^^^^^^^^^^^^^
AttributeError: 'str' object has no attribute 'value'

2024-10-24 16:33:05,742 - ERROR - run: 91 - ----------------Ошибка Check_file----------------
2024-10-24 16:33:43,022 - INFO - check_files: 73 - ----------------Запускаем Check_file----------------
2024-10-24 16:33:43,024 - INFO - check_files: 74 - Проверка данных
2024-10-24 16:33:43,024 - INFO - check_files: 86 - Запуск на выполнение
2024-10-24 16:33:43,027 - INFO - run: 35 - Начинаем проверку файлов
2024-10-24 16:33:47,365 - ERROR - run: 85 - descriptor 'strftime' for 'datetime.date' objects doesn't apply to a 'str' object
2024-10-24 16:33:47,374 - ERROR - run: 86 - Traceback (most recent call last):
  File "D:\python\Project_Check_File\check_file.py", line 50, in run
    print(datetime.datetime.strftime(df.iloc[3, 1]), '%d.%B %Y')
          ^^^^^^^^^^^^^^^^^^^^^^^^^^^^^^^^^^^^^^^^^
TypeError: descriptor 'strftime' for 'datetime.date' objects doesn't apply to a 'str' object

2024-10-24 16:33:47,374 - ERROR - run: 91 - ----------------Ошибка Check_file----------------
2024-10-24 16:34:37,136 - INFO - check_files: 73 - ----------------Запускаем Check_file----------------
2024-10-24 16:34:37,137 - INFO - check_files: 74 - Проверка данных
2024-10-24 16:34:37,138 - INFO - check_files: 86 - Запуск на выполнение
2024-10-24 16:34:37,140 - INFO - run: 35 - Начинаем проверку файлов
2024-10-24 16:34:44,149 - ERROR - run: 85 - strptime() takes exactly 2 arguments (1 given)
2024-10-24 16:34:44,152 - ERROR - run: 86 - Traceback (most recent call last):
  File "D:\python\Project_Check_File\check_file.py", line 50, in run
    print(datetime.datetime.strptime(df.iloc[3, 1]), '%d.%B %Y')
          ^^^^^^^^^^^^^^^^^^^^^^^^^^^^^^^^^^^^^^^^^
TypeError: strptime() takes exactly 2 arguments (1 given)

2024-10-24 16:34:44,152 - ERROR - run: 91 - ----------------Ошибка Check_file----------------
2024-10-24 16:36:26,466 - INFO - check_files: 73 - ----------------Запускаем Check_file----------------
2024-10-24 16:36:26,467 - INFO - check_files: 74 - Проверка данных
2024-10-24 16:36:26,467 - INFO - check_files: 86 - Запуск на выполнение
2024-10-24 16:36:26,469 - INFO - run: 35 - Начинаем проверку файлов
2024-10-24 16:36:49,279 - ERROR - run: 85 - time data 'ANALYZER' does not match format '%d.%B %Y'
2024-10-24 16:36:49,692 - ERROR - run: 86 - Traceback (most recent call last):
  File "D:\python\Project_Check_File\check_file.py", line 50, in run
    print(datetime.datetime.strptime(df.iloc[3, 1], '%d.%B %Y'))
          ^^^^^^^^^^^^^^^^^^^^^^^^^^^^^^^^^^^^^^^^^^^^^^^^^^^^^
  File "c:\Python312\Lib\_strptime.py", line 554, in _strptime_datetime
    tt, fraction, gmtoff_fraction = _strptime(data_string, format)
                                    ^^^^^^^^^^^^^^^^^^^^^^^^^^^^^^
  File "c:\Python312\Lib\_strptime.py", line 333, in _strptime
    raise ValueError("time data %r does not match format %r" %
ValueError: time data 'ANALYZER' does not match format '%d.%B %Y'

2024-10-24 16:36:51,210 - ERROR - run: 91 - ----------------Ошибка Check_file----------------
2024-10-24 16:39:25,013 - INFO - check_files: 73 - ----------------Запускаем Check_file----------------
2024-10-24 16:39:25,015 - INFO - check_files: 74 - Проверка данных
2024-10-24 16:39:25,015 - INFO - check_files: 86 - Запуск на выполнение
2024-10-24 16:39:25,017 - INFO - run: 35 - Начинаем проверку файлов
2024-10-24 16:39:28,566 - ERROR - run: 86 - time data 'ANALYZER' does not match format '%d.%B %Y'
2024-10-24 16:39:28,582 - ERROR - run: 87 - Traceback (most recent call last):
  File "D:\python\Project_Check_File\check_file.py", line 51, in run
    print(datetime.datetime.strptime(df.iloc[3, 1], '%d.%B %Y'))
          ^^^^^^^^^^^^^^^^^^^^^^^^^^^^^^^^^^^^^^^^^^^^^^^^^^^^^
  File "c:\Python312\Lib\_strptime.py", line 554, in _strptime_datetime
    tt, fraction, gmtoff_fraction = _strptime(data_string, format)
                                    ^^^^^^^^^^^^^^^^^^^^^^^^^^^^^^
  File "c:\Python312\Lib\_strptime.py", line 333, in _strptime
    raise ValueError("time data %r does not match format %r" %
ValueError: time data 'ANALYZER' does not match format '%d.%B %Y'

2024-10-24 16:39:28,582 - ERROR - run: 92 - ----------------Ошибка Check_file----------------
2024-10-24 16:39:45,532 - INFO - check_files: 73 - ----------------Запускаем Check_file----------------
2024-10-24 16:39:45,533 - INFO - check_files: 74 - Проверка данных
2024-10-24 16:39:45,533 - INFO - check_files: 86 - Запуск на выполнение
2024-10-24 16:39:45,535 - INFO - run: 35 - Начинаем проверку файлов
2024-10-24 16:39:48,892 - ERROR - run: 86 - time data '09.Oct 2024' does not match format '%d.%B %Y'
2024-10-24 16:39:48,892 - ERROR - run: 87 - Traceback (most recent call last):
  File "D:\python\Project_Check_File\check_file.py", line 51, in run
    print(datetime.datetime.strptime(df.iloc[2, 1], '%d.%B %Y'))
          ^^^^^^^^^^^^^^^^^^^^^^^^^^^^^^^^^^^^^^^^^^^^^^^^^^^^^
  File "c:\Python312\Lib\_strptime.py", line 554, in _strptime_datetime
    tt, fraction, gmtoff_fraction = _strptime(data_string, format)
                                    ^^^^^^^^^^^^^^^^^^^^^^^^^^^^^^
  File "c:\Python312\Lib\_strptime.py", line 333, in _strptime
    raise ValueError("time data %r does not match format %r" %
ValueError: time data '09.Oct 2024' does not match format '%d.%B %Y'

2024-10-24 16:39:48,892 - ERROR - run: 92 - ----------------Ошибка Check_file----------------
2024-10-24 16:41:11,049 - INFO - check_files: 73 - ----------------Запускаем Check_file----------------
2024-10-24 16:41:11,050 - INFO - check_files: 74 - Проверка данных
2024-10-24 16:41:11,050 - INFO - check_files: 86 - Запуск на выполнение
2024-10-24 16:41:11,052 - INFO - run: 35 - Начинаем проверку файлов
2024-10-24 16:41:31,496 - INFO - check_files: 73 - ----------------Запускаем Check_file----------------
2024-10-24 16:41:31,497 - INFO - check_files: 74 - Проверка данных
2024-10-24 16:41:31,497 - INFO - check_files: 86 - Запуск на выполнение
2024-10-24 16:41:31,500 - INFO - run: 35 - Начинаем проверку файлов
